Workbook
Name income_quartile: Table4[#All]
Name Power_Query: #REF!
Name powerquery: #REF!

Sheet Project Overview

Sheet Campaign Data
A1: Income | B1: IncomeGroup | C1: Kidhome | D1: Teenhome | E1: Recency | F1: RecencyGroup | G1: MntWines | H1: MntFruits | I1: MntMeatProducts | J1: MntFishProducts | K1: MntSweetProducts | L1: MntGoldProds | M1: TopProduct | N1: NumDealsPurchases | O1: NumWebPurchases | P1: NumCatalogPurchases | Q1: NumStorePurchases | R1: NumWebVisitsMonth | S1: AcceptedCmp3 | T1: AcceptedCmp4 | U1: AcceptedCmp5 | V1: AcceptedCmp1 | W1: AcceptedCmp2 | X1: Complain | Y1: Z_CostContact | Z1: Z_Revenue | AA1: Response | AB1: Age | AC1: AgeGroup | AD1: Customer_Days | AE1: marital_Divorced | AF1: marital_Married | AG1: marital_Single | AH1: marital_Together | AI1: marital_Widow | AJ1: MaritalStatus | AK1: MaritalGroup | AL1: education_2n Cycle | AM1: education_Basic | AN1: education_Graduation | AO1: education_Master | AP1: education_PhD | AQ1: EducationLevel | AR1: EducationGroup | AS1: MntTotal | AT1: MntRegularProds | AU1: AcceptedCmpOverall | AV1: TotalKids | AW1: SpendingSegment | AX1: DominantChannel_Python | AY1: PreferedChannel | AZ1: TotalPurchases | BA1: AcceptedFlag | BB1: Frequency | BC1: Monetary | BD1: Recency_Score | BE1: Frequency_Score | BF1: Monetary_Score | BG1: RFM | BH1: RFM_Score | BI1: Customer_Segment | BJ1: WineSpending | BK1: SweetSpending | BL1: GoldSpending | BM1: ID
A2: 58138 | B2: =IF(A2 <= 'Additional Data'!$B$2,"Low", IF(A2 <='Additional Data'!$B$3, "Medium", "High")) -> Medium | C2: 0 | D2: 0 | E2: 58 | F2: =IF(E2<=7,"Very Recent",IF(E2<=30,"Recent",IF(E2<=60,"Mid","Old"))) -> Mid | G2: 635 | H2: 88 | I2: 546 | J2: 172 | K2: 88 | L2: 88 | M2: =INDEX('Additional Data'!$H$2:$M$2, MATCH(MAX(G2:L2), G2:L2,0)) -> 0 | N2: 3 | O2: 8 | P2: 10 | Q2: 4 | R2: 7 | S2: 0 | T2: 0 | U2: 0 | V2: 0 | W2: 0 | X2: 0 | Y2: 3 | Z2: 11 | AA2: 1 | AB2: 63 | AC2: {=_xlfn.IFS(AB2 < 30, "< 30", AB2 < 40, "30-39", AB2 < 50, "40-49", AB2 >= 50, "50+")} -> 50+ | AD2: 2822 | AE2: 0 | AF2: 0 | AG2: 1 | AH2: 0 | AI2: 0 | AJ2: {=_xlfn.IFS(Table1[[#This Row],[marital_Divorced]] = 1, "Divorced", Table1[[#This Row],[marital_Married]] = 1, "Married", Table1[[#This Row],[marital_Single]] = 1, "Single", Table1[[#This Row],[marital_Together]] = 1, "Together", Table1[[#This Row],[marital_Widow]] = 1, "Widow")} -> Single | AK2: =IF(OR(Table1[[#This Row],[MaritalStatus]] = "Married", Table1[[#This Row],[MaritalStatus]] = "Together"), "Partner", IF(OR(Table1[[#This Row],[MaritalStatus]] = "Single",Table1[[#This Row],[MaritalStatus]] = "Divorced", Table1[[#This Row],[MaritalStatus]] = "Widow"), "Alone", "Other")) -> Alone | AL2: 0 | AM2: 0 | AN2: 1 | AO2: 0 | AP2: 0 | AQ2: {=_xlfn.IFS(Table1[[#This Row],[education_2n Cycle]] = 1, "2n Cycle", Table1[[#This Row],[education_Basic]] = 1, "Basic", Table1[[#This Row],[education_Graduation]] = 1, "Graduation", Table1[[#This Row],[education_Master]] = 1, "Master", Table1[[#This Row],[education_PhD]] = 1, "PhD")} -> Graduation | AR2: {=_xlfn.IFS(Table1[[#This Row],[EducationLevel]] = "Graduation", "Graduate", Table1[[#This Row],[EducationLevel]] = "2n Cycle", "Undergraduate", Table1[[#This Row],[EducationLevel]] = "Basic", "Undergraduate", Table1[[#This Row],[EducationLevel]] = "Master", "Postgraduate", Table1[[#This Row],[EducationLevel]] = "PhD", "Postgraduate")} -> Graduate | AS2: 1529 | AT2: 1441 | AU2: 0 | AV2: 0 | AW2: High Spender | AX2: NumCatalogPurchases | AY2: =IF(AND(O2 >= P2, O2 >= Q2), "Web", IF(AND(P2 >= O2, P2 >= Q2), "Catalog", "Store")) -> Catalog | AZ2: 22 | BA2: Not Accepted | BB2: =SUM(O2:Q2) -> 22 | BC2: =SUM(G2:L2) -> 1617 | BD2: =(1-_xlfn.PERCENTRANK.INC($E:$E,E2,1))*10 -> 5 | BE2: =_xlfn.PERCENTRANK.INC($BB:$BB,BB2,1)*10 -> 8 | BF2: =_xlfn.PERCENTRANK.INC($BC:$BC,BC2,1)*10 -> 9 | BG2: =SUM(BD2:BF2) -> 22 | BH2: =_xlfn.PERCENTRANK.INC($BG:$BG,BG2,1)*10 -> 8 | BI2: =VLOOKUP(BH2,'Additional Data'!$E$1:$F$12,2,FALSE) -> Top Customer | BJ2: =IF(G2 <= 'Additional Data'!$Q$2, "Low", IF(G2 <= 'Additional Data'!$Q$3, "Medium", "High")) -> High | BK2: =IF(K2 <= 'Additional Data'!$V$2, "Low", IF(K2 <= 'Additional Data'!$V$3, "Medium", "High")) -> High | BL2: =IF(L2 <= 'Additional Data'!$AA$2, "Low", IF(L2 <= 'Additional Data'!$AA$3, "Medium", "High")) -> High | BM2: 1
A3: 46344 | B3: =IF(A3 <= 'Additional Data'!$B$2,"Low", IF(A3 <='Additional Data'!$B$3, "Medium", "High")) -> Medium | C3: 1 | D3: 1 | E3: 38 | F3: =IF(E3<=7,"Very Recent",IF(E3<=30,"Recent",IF(E3<=60,"Mid","Old"))) -> Mid | G3: 11 | H3: 1 | I3: 6 | J3: 2 | K3: 1 | L3: 6 | M3: =INDEX('Additional Data'!$H$2:$M$2, MATCH(MAX(G3:L3), G3:L3,0)) -> 0 | N3: 2 | O3: 1 | P3: 1 | Q3: 2 | R3: 5 | S3: 0 | T3: 0 | U3: 0 | V3: 0 | W3: 0 | X3: 0 | Y3: 3 | Z3: 11 | AA3: 0 | AB3: 66 | AC3: {=_xlfn.IFS(AB3 < 30, "< 30", AB3 < 40, "30-39", AB3 < 50, "40-49", AB3 >= 50, "50+")} -> 50+ | AD3: 2272 | AE3: 0 | AF3: 0 | AG3: 1 | AH3: 0 | AI3: 0 | AJ3: {=_xlfn.IFS(Table1[[#This Row],[marital_Divorced]] = 1, "Divorced", Table1[[#This Row],[marital_Married]] = 1, "Married", Table1[[#This Row],[marital_Single]] = 1, "Single", Table1[[#This Row],[marital_Together]] = 1, "Together", Table1[[#This Row],[marital_Widow]] = 1, "Widow")} -> Single | AK3: =IF(OR(Table1[[#This Row],[MaritalStatus]] = "Married", Table1[[#This Row],[MaritalStatus]] = "Together"), "Partner", IF(OR(Table1[[#This Row],[MaritalStatus]] = "Single",Table1[[#This Row],[MaritalStatus]] = "Divorced", Table1[[#This Row],[MaritalStatus]] = "Widow"), "Alone", "Other")) -> Alone | AL3: 0 | AM3: 0 | AN3: 1 | AO3: 0 | AP3: 0 | AQ3: {=_xlfn.IFS(Table1[[#This Row],[education_2n Cycle]] = 1, "2n Cycle", Table1[[#This Row],[education_Basic]] = 1, "Basic", Table1[[#This Row],[education_Graduation]] = 1, "Graduation", Table1[[#This Row],[education_Master]] = 1, "Master", Table1[[#This Row],[education_PhD]] = 1, "PhD")} -> Graduation | AR3: {=_xlfn.IFS(Table1[[#This Row],[EducationLevel]] = "Graduation", "Graduate", Table1[[#This Row],[EducationLevel]] = "2n Cycle", "Undergraduate", Table1[[#This Row],[EducationLevel]] = "Basic", "Undergraduate", Table1[[#This Row],[EducationLevel]] = "Master", "Postgraduate", Table1[[#This Row],[EducationLevel]] = "PhD", "Postgraduate")} -> Graduate | AS3: 21 | AT3: 15 | AU3: 0 | AV3: 2 | AW3: Low Spender | AX3: NumStorePurchases | AY3: =IF(AND(O3 >= P3, O3 >= Q3), "Web", IF(AND(P3 >= O3, P3 >= Q3), "Catalog", "Store")) -> Store | AZ3: 4 | BA3: Not Accepted | BB3: =SUM(O3:Q3) -> 4 | BC3: =SUM(G3:L3) -> 27 | BD3: =(1-_xlfn.PERCENTRANK.INC($E:$E,E3,1))*10 -> 7 | BE3: =_xlfn.PERCENTRANK.INC($BB:$BB,BB3,1)*10 -> 0 | BF3: =_xlfn.PERCENTRANK.INC($BC:$BC,BC3,1)*10 -> 0 | BG3: =SUM(BD3:BF3) -> 7 | BH3: =_xlfn.PERCENTRANK.INC($BG:$BG,BG3,1)*10 -> 1 | BI3: =VLOOKUP(BH3,'Additional Data'!$E$1:$F$12,2,FALSE) -> Churned Customer | BJ3: =IF(G3 <= 'Additional Data'!$Q$2, "Low", IF(G3 <= 'Additional Data'!$Q$3, "Medium", "High")) -> Low | BK3: =IF(K3 <= 'Additional Data'!$V$2, "Low", IF(K3 <= 'Additional Data'!$V$3, "Medium", "High")) -> Low | BL3: =IF(L3 <= 'Additional Data'!$AA$2, "Low", IF(L3 <= 'Additional Data'!$AA$3, "Medium", "High")) -> Low | BM3: 2
A4: 71613 | B4: =IF(A4 <= 'Additional Data'!$B$2,"Low", IF(A4 <='Additional Data'!$B$3, "Medium", "High")) -> High | C4: 0 | D4: 0 | E4: 26 | F4: =IF(E4<=7,"Very Recent",IF(E4<=30,"Recent",IF(E4<=60,"Mid","Old"))) -> Recent | G4: 426 | H4: 49 | I4: 127 | J4: 111 | K4: 21 | L4: 42 | M4: =INDEX('Additional Data'!$H$2:$M$2, MATCH(MAX(G4:L4), G4:L4,0)) -> 0 | N4: 1 | O4: 8 | P4: 2 | Q4: 10 | R4: 4 | S4: 0 | T4: 0 | U4: 0 | V4: 0 | W4: 0 | X4: 0 | Y4: 3 | Z4: 11 | AA4: 0 | AB4: 55 | AC4: {=_xlfn.IFS(AB4 < 30, "< 30", AB4 < 40, "30-39", AB4 < 50, "40-49", AB4 >= 50, "50+")} -> 50+ | AD4: 2471 | AE4: 0 | AF4: 0 | AG4: 0 | AH4: 1 | AI4: 0 | AJ4: {=_xlfn.IFS(Table1[[#This Row],[marital_Divorced]] = 1, "Divorced", Table1[[#This Row],[marital_Married]] = 1, "Married", Table1[[#This Row],[marital_Single]] = 1, "Single", Table1[[#This Row],[marital_Together]] = 1, "Together", Table1[[#This Row],[marital_Widow]] = 1, "Widow")} -> Together | AK4: =IF(OR(Table1[[#This Row],[MaritalStatus]] = "Married", Table1[[#This Row],[MaritalStatus]] = "Together"), "Partner", IF(OR(Table1[[#This Row],[MaritalStatus]] = "Single",Table1[[#This Row],[MaritalStatus]] = "Divorced", Table1[[#This Row],[MaritalStatus]] = "Widow"), "Alone", "Other")) -> Partner | AL4: 0 | AM4: 0 | AN4: 1 | AO4: 0 | AP4: 0 | AQ4: {=_xlfn.IFS(Table1[[#This Row],[education_2n Cycle]] = 1, "2n Cycle", Table1[[#This Row],[education_Basic]] = 1, "Basic", Table1[[#This Row],[education_Graduation]] = 1, "Graduation", Table1[[#This Row],[education_Master]] = 1, "Master", Table1[[#This Row],[education_PhD]] = 1, "PhD")} -> Graduation | AR4: {=_xlfn.IFS(Table1[[#This Row],[EducationLevel]] = "Graduation", "Graduate", Table1[[#This Row],[EducationLevel]] = "2n Cycle", "Undergraduate", Table1[[#This Row],[EducationLevel]] = "Basic", "Undergraduate", Table1[[#This Row],[EducationLevel]] = "Master", "Postgraduate", Table1[[#This Row],[EducationLevel]] = "PhD", "Postgraduate")} -> Graduate | AS4: 734 | AT4: 692 | AU4: 0 | AV4: 0 | AW4: Medium-High Spender | AX4: NumStorePurchases | AY4: =IF(AND(O4 >= P4, O4 >= Q4), "Web", IF(AND(P4 >= O4, P4 >= Q4), "Catalog", "Store")) -> Store | AZ4: 20 | BA4: Not Accepted | BB4: =SUM(O4:Q4) -> 20 | BC4: =SUM(G4:L4) -> 776 | BD4: =(1-_xlfn.PERCENTRANK.INC($E:$E,E4,1))*10 -> 8 | BE4: =_xlfn.PERCENTRANK.INC($BB:$BB,BB4,1)*10 -> 7 | BF4: =_xlfn.PERCENTRANK.INC($BC:$BC,BC4,1)*10 -> 6 | BG4: =SUM(BD4:BF4) -> 21 | BH4: =_xlfn.PERCENTRANK.INC($BG:$BG,BG4,1)*10 -> 8 | BI4: =VLOOKUP(BH4,'Additional Data'!$E$1:$F$12,2,FALSE) -> Top Customer | BJ4: =IF(G4 <= 'Additional Data'!$Q$2, "Low", IF(G4 <= 'Additional Data'!$Q$3, "Medium", "High")) -> Medium | BK4: =IF(K4 <= 'Additional Data'!$V$2, "Low", IF(K4 <= 'Additional Data'!$V$3, "Medium", "High")) -> Medium | BL4: =IF(L4 <= 'Additional Data'!$AA$2, "Low", IF(L4 <= 'Additional Data'!$AA$3, "Medium", "High")) -> Medium | BM4: 3
A5: 26646 | B5: =IF(A5 <= 'Additional Data'!$B$2,"Low", IF(A5 <='Additional Data'!$B$3, "Medium", "High")) -> Low | C5: 1 | D5: 0 | E5: 26 | F5: =IF(E5<=7,"Very Recent",IF(E5<=30,"Recent",IF(E5<=60,"Mid","Old"))) -> Recent | G5: 11 | H5: 4 | I5: 20 | J5: 10 | K5: 3 | L5: 5 | M5: =INDEX('Additional Data'!$H$2:$M$2, MATCH(MAX(G5:L5), G5:L5,0)) -> 0 | N5: 2 | O5: 2 | P5: 0 | Q5: 4 | R5: 6 | S5: 0 | T5: 0 | U5: 0 | V5: 0 | W5: 0 | X5: 0 | Y5: 3 | Z5: 11 | AA5: 0 | AB5: 36 | AC5: {=_xlfn.IFS(AB5 < 30, "< 30", AB5 < 40, "30-39", AB5 < 50, "40-49", AB5 >= 50, "50+")} -> 30-39 | AD5: 2298 | AE5: 0 | AF5: 0 | AG5: 0 | AH5: 1 | AI5: 0 | AJ5: {=_xlfn.IFS(Table1[[#This Row],[marital_Divorced]] = 1, "Divorced", Table1[[#This Row],[marital_Married]] = 1, "Married", Table1[[#This Row],[marital_Single]] = 1, "Single", Table1[[#This Row],[marital_Together]] = 1, "Together", Table1[[#This Row],[marital_Widow]] = 1, "Widow")} -> Together | AK5: =IF(OR(Table1[[#This Row],[MaritalStatus]] = "Married", Table1[[#This Row],[MaritalStatus]] = "Together"), "Partner", IF(OR(Table1[[#This Row],[MaritalStatus]] = "Single",Table1[[#This Row],[MaritalStatus]] = "Divorced", Table1[[#This Row],[MaritalStatus]] = "Widow"), "Alone", "Other")) -> Partner | AL5: 0 | AM5: 0 | AN5: 1 | AO5: 0 | AP5: 0 | AQ5: {=_xlfn.IFS(Table1[[#This Row],[education_2n Cycle]] = 1, "2n Cycle", Table1[[#This Row],[education_Basic]] = 1, "Basic", Table1[[#This Row],[education_Graduation]] = 1, "Graduation", Table1[[#This Row],[education_Master]] = 1, "Master", Table1[[#This Row],[education_PhD]] = 1, "PhD")} -> Graduation | AR5: {=_xlfn.IFS(Table1[[#This Row],[EducationLevel]] = "Graduation", "Graduate", Table1[[#This Row],[EducationLevel]] = "2n Cycle", "Undergraduate", Table1[[#This Row],[EducationLevel]] = "Basic", "Undergraduate", Table1[[#This Row],[EducationLevel]] = "Master", "Postgraduate", Table1[[#This Row],[EducationLevel]] = "PhD", "Postgraduate")} -> Graduate | AS5: 48 | AT5: 43 | AU5: 0 | AV5: 1 | AW5: Low Spender | AX5: NumStorePurchases | AY5: =IF(AND(O5 >= P5, O5 >= Q5), "Web", IF(AND(P5 >= O5, P5 >= Q5), "Catalog", "Store")) -> Store | AZ5: 6 | BA5: Not Accepted | BB5: =SUM(O5:Q5) -> 6 | BC5: =SUM(G5:L5) -> 53 | BD5: =(1-_xlfn.PERCENTRANK.INC($E:$E,E5,1))*10 -> 8 | BE5: =_xlfn.PERCENTRANK.INC($BB:$BB,BB5,1)*10 -> 2 | BF5: =_xlfn.PERCENTRANK.INC($BC:$BC,BC5,1)*10 -> 1 | BG5: =SUM(BD5:BF5) -> 11 | BH5: =_xlfn.PERCENTRANK.INC($BG:$BG,BG5,1)*10 -> 3 | BI5: =VLOOKUP(BH5,'Additional Data'!$E$1:$F$12,2,FALSE) -> At Risk | BJ5: =IF(G5 <= 'Additional Data'!$Q$2, "Low", IF(G5 <= 'Additional Data'!$Q$3, "Medium", "High")) -> Low | BK5: =IF(K5 <= 'Additional Data'!$V$2, "Low", IF(K5 <= 'Additional Data'!$V$3, "Medium", "High")) -> Medium | BL5: =IF(L5 <= 'Additional Data'!$AA$2, "Low", IF(L5 <= 'Additional Data'!$AA$3, "Medium", "High")) -> Low | BM5: 4
A6: 58293 | B6: =IF(A6 <= 'Additional Data'!$B$2,"Low", IF(A6 <='Additional Data'!$B$3, "Medium", "High")) -> Medium | C6: 1 | D6: 0 | E6: 94 | F6: =IF(E6<=7,"Very Recent",IF(E6<=30,"Recent",IF(E6<=60,"Mid","Old"))) -> Old | G6: 173 | H6: 43 | I6: 118 | J6: 46 | K6: 27 | L6: 15 | M6: =INDEX('Additional Data'!$H$2:$M$2, MATCH(MAX(G6:L6), G6:L6,0)) -> 0 | N6: 5 | O6: 5 | P6: 3 | Q6: 6 | R6: 5 | S6: 0 | T6: 0 | U6: 0 | V6: 0 | W6: 0 | X6: 0 | Y6: 3 | Z6: 11 | AA6: 0 | AB6: 39 | AC6: {=_xlfn.IFS(AB6 < 30, "< 30", AB6 < 40, "30-39", AB6 < 50, "40-49", AB6 >= 50, "50+")} -> 30-39 | AD6: 2320 | AE6: 0 | AF6: 1 | AG6: 0 | AH6: 0 | AI6: 0 | AJ6: {=_xlfn.IFS(Table1[[#This Row],[marital_Divorced]] = 1, "Divorced", Table1[[#This Row],[marital_Married]] = 1, "Married", Table1[[#This Row],[marital_Single]] = 1, "Single", Table1[[#This Row],[marital_Together]] = 1, "Together", Table1[[#This Row],[marital_Widow]] = 1, "Widow")} -> Married | AK6: =IF(OR(Table1[[#This Row],[MaritalStatus]] = "Married", Table1[[#This Row],[MaritalStatus]] = "Together"), "Partner", IF(OR(Table1[[#This Row],[MaritalStatus]] = "Single",Table1[[#This Row],[MaritalStatus]] = "Divorced", Table1[[#This Row],[MaritalStatus]] = "Widow"), "Alone", "Other")) -> Partner | AL6: 0 | AM6: 0 | AN6: 0 | AO6: 0 | AP6: 1 | AQ6: {=_xlfn.IFS(Table1[[#This Row],[education_2n Cycle]] = 1, "2n Cycle", Table1[[#This Row],[education_Basic]] = 1, "Basic", Table1[[#This Row],[education_Graduation]] = 1, "Graduation", Table1[[#This Row],[education_Master]] = 1, "Master", Table1[[#This Row],[education_PhD]] = 1, "PhD")} -> PhD | AR6: {=_xlfn.IFS(Table1[[#This Row],[EducationLevel]] = "Graduation", "Graduate", Table1[[#This Row],[EducationLevel]] = "2n Cycle", "Undergraduate", Table1[[#This Row],[EducationLevel]] = "Basic", "Undergraduate", Table1[[#This Row],[EducationLevel]] = "Master", "Postgraduate", Table1[[#This Row],[EducationLevel]] = "PhD", "Postgraduate")} -> Postgraduate | AS6: 407 | AT6: 392 | AU6: 0 | AV6: 1 | AW6: Medium-High Spender | AX6: NumStorePurchases | AY6: =IF(AND(O6 >= P6, O6 >= Q6), "Web", IF(AND(P6 >= O6, P6 >= Q6), "Catalog", "Store")) -> Store | AZ6: 14 | BA6: Not Accepted | BB6: =SUM(O6:Q6) -> 14 | BC6: =SUM(G6:L6) -> 422 | BD6: =(1-_xlfn.PERCENTRANK.INC($E:$E,E6,1))*10 -> 1 | BE6: =_xlfn.PERCENTRANK.INC($BB:$BB,BB6,1)*10 -> 5 | BF6: =_xlfn.PERCENTRANK.INC($BC:$BC,BC6,1)*10 -> 5 | BG6: =SUM(BD6:BF6) -> 11 | BH6: =_xlfn.PERCENTRANK.INC($BG:$BG,BG6,1)*10 -> 3 | BI6: =VLOOKUP(BH6,'Additional Data'!$E$1:$F$12,2,FALSE) -> At Risk | BJ6: =IF(G6 <= 'Additional Data'!$Q$2, "Low", IF(G6 <= 'Additional Data'!$Q$3, "Medium", "High")) -> Medium | BK6: =IF(K6 <= 'Additional Data'!$V$2, "Low", IF(K6 <= 'Additional Data'!$V$3, "Medium", "High")) -> Medium | BL6: =IF(L6 <= 'Additional Data'!$AA$2, "Low", IF(L6 <= 'Additional Data'!$AA$3, "Medium", "High")) -> Medium | BM6: 5
A7: 62513 | B7: =IF(A7 <= 'Additional Data'!$B$2,"Low", IF(A7 <='Additional Data'!$B$3, "Medium", "High")) -> Medium | C7: 0 | D7: 1 | E7: 16 | F7: =IF(E7<=7,"Very Recent",IF(E7<=30,"Recent",IF(E7<=60,"Mid","Old"))) -> Recent | G7: 520 | H7: 42 | I7: 98 | J7: 0 | K7: 42 | L7: 14 | M7: =INDEX('Additional Data'!$H$2:$M$2, MATCH(MAX(G7:L7), G7:L7,0)) -> 0 | N7: 2 | O7: 6 | P7: 4 | Q7: 10 | R7: 6 | S7: 0 | T7: 0 | U7: 0 | V7: 0 | W7: 0 | X7: 0 | Y7: 3 | Z7: 11 | AA7: 0 | AB7: 53 | AC7: {=_xlfn.IFS(AB7 < 30, "< 30", AB7 < 40, "30-39", AB7 < 50, "40-49", AB7 >= 50, "50+")} -> 50+ | AD7: 2452 | AE7: 0 | AF7: 0 | AG7: 0 | AH7: 1 | AI7: 0 | AJ7: {=_xlfn.IFS(Table1[[#This Row],[marital_Divorced]] = 1, "Divorced", Table1[[#This Row],[marital_Married]] = 1, "Married", Table1[[#This Row],[marital_Single]] = 1, "Single", Table1[[#This Row],[marital_Together]] = 1, "Together", Table1[[#This Row],[marital_Widow]] = 1, "Widow")} -> Together | AK7: =IF(OR(Table1[[#This Row],[MaritalStatus]] = "Married", Table1[[#This Row],[MaritalStatus]] = "Together"), "Partner", IF(OR(Table1[[#This Row],[MaritalStatus]] = "Single",Table1[[#This Row],[MaritalStatus]] = "Divorced", Table1[[#This Row],[MaritalStatus]] = "Widow"), "Alone", "Other")) -> Partner | AL7: 0 | AM7: 0 | AN7: 0 | AO7: 1 | AP7: 0 | AQ7: {=_xlfn.IFS(Table1[[#This Row],[education_2n Cycle]] = 1, "2n Cycle", Table1[[#This Row],[education_Basic]] = 1, "Basic", Table1[[#This Row],[education_Graduation]] = 1, "Graduation", Table1[[#This Row],[education_Master]] = 1, "Master", Table1[[#This Row],[education_PhD]] = 1, "PhD")} -> Master | AR7: {=_xlfn.IFS(Table1[[#This Row],[EducationLevel]] = "Graduation", "Graduate", Table1[[#This Row],[EducationLevel]] = "2n Cycle", "Undergraduate", Table1[[#This Row],[EducationLevel]] = "Basic", "Undergraduate", Table1[[#This Row],[EducationLevel]] = "Master", "Postgraduate", Table1[[#This Row],[EducationLevel]] = "PhD", "Postgraduate")} -> Postgraduate | AS7: 702 | AT7: 688 | AU7: 0 | AV7: 1 | AW7: Medium-High Spender | AX7: NumStorePurchases | AY7: =IF(AND(O7 >= P7, O7 >= Q7), "Web", IF(AND(P7 >= O7, P7 >= Q7), "Catalog", "Store")) -> Store | AZ7: 20 | BA7: Not Accepted | BB7: =SUM(O7:Q7) -> 20 | BC7: =SUM(G7:L7) -> 716 | BD7: =(1-_xlfn.PERCENTRANK.INC($E:$E,E7,1))*10 -> 9 | BE7: =_xlfn.PERCENTRANK.INC($BB:$BB,BB7,1)*10 -> 7 | BF7: =_xlfn.PERCENTRANK.INC($BC:$BC,BC7,1)*10 -> 6 | BG7: =SUM(BD7:BF7) -> 22 | BH7: =_xlfn.PERCENTRANK.INC($BG:$BG,BG7,1)*10 -> 8 | BI7: =VLOOKUP(BH7,'Additional Data'!$E$1:$F$12,2,FALSE) -> Top Customer | BJ7: =IF(G7 <= 'Additional Data'!$Q$2, "Low", IF(G7 <= 'Additional Data'!$Q$3, "Medium", "High")) -> High | BK7: =IF(K7 <= 'Additional Data'!$V$2, "Low", IF(K7 <= 'Additional Data'!$V$3, "Medium", "High")) -> High | BL7: =IF(L7 <= 'Additional Data'!$AA$2, "Low", IF(L7 <= 'Additional Data'!$AA$3, "Medium", "High")) -> Medium | BM7: 6
A8: 55635 | B8: =IF(A8 <= 'Additional Data'!$B$2,"Low", IF(A8 <='Additional Data'!$B$3, "Medium", "High")) -> Medium | C8: 0 | D8: 1 | E8: 34 | F8: =IF(E8<=7,"Very Recent",IF(E8<=30,"Recent",IF(E8<=60,"Mid","Old"))) -> Mid | G8: 235 | H8: 65 | I8: 164 | J8: 50 | K8: 49 | L8: 27 | M8: =INDEX('Additional Data'!$H$2:$M$2, MATCH(MAX(G8:L8), G8:L8,0)) -> 0 | N8: 4 | O8: 7 | P8: 3 | Q8: 7 | R8: 6 | S8: 0 | T8: 0 | U8: 0 | V8: 0 | W8: 0 | X8: 0 | Y8: 3 | Z8: 11 | AA8: 0 | AB8: 49 | AC8: {=_xlfn.IFS(AB8 < 30, "< 30", AB8 < 40, "30-39", AB8 < 50, "40-49", AB8 >= 50, "50+")} -> 40-49 | AD8: 2752 | AE8: 1 | AF8: 0 | AG8: 0 | AH8: 0 | AI8: 0 | AJ8: {=_xlfn.IFS(Table1[[#This Row],[marital_Divorced]] = 1, "Divorced", Table1[[#This Row],[marital_Married]] = 1, "Married", Table1[[#This Row],[marital_Single]] = 1, "Single", Table1[[#This Row],[marital_Together]] = 1, "Together", Table1[[#This Row],[marital_Widow]] = 1, "Widow")} -> Divorced | AK8: =IF(OR(Table1[[#This Row],[MaritalStatus]] = "Married", Table1[[#This Row],[MaritalStatus]] = "Together"), "Partner", IF(OR(Table1[[#This Row],[MaritalStatus]] = "Single",Table1[[#This Row],[MaritalStatus]] = "Divorced", Table1[[#This Row],[MaritalStatus]] = "Widow"), "Alone", "Other")) -> Alone | AL8: 0 | AM8: 0 | AN8: 1 | AO8: 0 | AP8: 0 | AQ8: {=_xlfn.IFS(Table1[[#This Row],[education_2n Cycle]] = 1, "2n Cycle", Table1[[#This Row],[education_Basic]] = 1, "Basic", Table1[[#This Row],[education_Graduation]] = 1, "Graduation", Table1[[#This Row],[education_Master]] = 1, "Master", Table1[[#This Row],[education_PhD]] = 1, "PhD")} -> Graduation | AR8: {=_xlfn.IFS(Table1[[#This Row],[EducationLevel]] = "Graduation", "Graduate", Table1[[#This Row],[EducationLevel]] = "2n Cycle", "Undergraduate", Table1[[#This Row],[EducationLevel]] = "Basic", "Undergraduate", Table1[[#This Row],[EducationLevel]] = "Master", "Postgraduate", Table1[[#This Row],[EducationLevel]] = "PhD", "Postgraduate")} -> Graduate | AS8: 563 | AT8: 536 | AU8: 0 | AV8: 1 | AW8: Medium-High Spender | AX8: NumWebPurchases | AY8: =IF(AND(O8 >= P8, O8 >= Q8), "Web", IF(AND(P8 >= O8, P8 >= Q8), "Catalog", "Store")) -> Web | AZ8: 17 | BA8: Not Accepted | BB8: =SUM(O8:Q8) -> 17 | BC8: =SUM(G8:L8) -> 590 | BD8: =(1-_xlfn.PERCENTRANK.INC($E:$E,E8,1))*10 -> 7 | BE8: =_xlfn.PERCENTRANK.INC($BB:$BB,BB8,1)*10 -> 6 | BF8: =_xlfn.PERCENTRANK.INC($BC:$BC,BC8,1)*10 -> 5 | BG8: =SUM(BD8:BF8) -> 18 | BH8: =_xlfn.PERCENTRANK.INC($BG:$BG,BG8,1)*10 -> 6 | BI8: =VLOOKUP(BH8,'Additional Data'!$E$1:$F$12,2,FALSE) -> Loyal Customer | BJ8: =IF(G8 <= 'Additional Data'!$Q$2, "Low", IF(G8 <= 'Additional Data'!$Q$3, "Medium", "High")) -> Medium | BK8: =IF(K8 <= 'Additional Data'!$V$2, "Low", IF(K8 <= 'Additional Data'!$V$3, "Medium", "High")) -> High | BL8: =IF(L8 <= 'Additional Data'!$AA$2, "Low", IF(L8 <= 'Additional Data'!$AA$3, "Medium", "High")) -> Medium | BM8: 7
A9: 33454 | B9: =IF(A9 <= 'Additional Data'!$B$2,"Low", IF(A9 <='Additional Data'!$B$3, "Medium", "High")) -> Low | C9: 1 | D9: 0 | E9: 32 | F9: =IF(E9<=7,"Very Recent",IF(E9<=30,"Recent",IF(E9<=60,"Mid","Old"))) -> Mid | G9: 76 | H9: 10 | I9: 56 | J9: 3 | K9: 1 | L9: 23 | M9: =INDEX('Additional Data'!$H$2:$M$2, MATCH(MAX(G9:L9), G9:L9,0)) -> 0 | N9: 2 | O9: 4 | P9: 0 | Q9: 4 | R9: 8 | S9: 0 | T9: 0 | U9: 0 | V9: 0 | W9: 0 | X9: 0 | Y9: 3 | Z9: 11 | AA9: 0 | AB9: 35 | AC9: {=_xlfn.IFS(AB9 < 30, "< 30", AB9 < 40, "30-39", AB9 < 50, "40-49", AB9 >= 50, "50+")} -> 30-39 | AD9: 2576 | AE9: 0 | AF9: 1 | AG9: 0 | AH9: 0 | AI9: 0 | AJ9: {=_xlfn.IFS(Table1[[#This Row],[marital_Divorced]] = 1, "Divorced", Table1[[#This Row],[marital_Married]] = 1, "Married", Table1[[#This Row],[marital_Single]] = 1, "Single", Table1[[#This Row],[marital_Together]] = 1, "Together", Table1[[#This Row],[marital_Widow]] = 1, "Widow")} -> Married | AK9: =IF(OR(Table1[[#This Row],[MaritalStatus]] = "Married", Table1[[#This Row],[MaritalStatus]] = "Together"), "Partner", IF(OR(Table1[[#This Row],[MaritalStatus]] = "Single",Table1[[#This Row],[MaritalStatus]] = "Divorced", Table1[[#This Row],[MaritalStatus]] = "Widow"), "Alone", "Other")) -> Partner | AL9: 0 | AM9: 0 | AN9: 0 | AO9: 0 | AP9: 1 | AQ9: {=_xlfn.IFS(Table1[[#This Row],[education_2n Cycle]] = 1, "2n Cycle", Table1[[#This Row],[education_Basic]] = 1, "Basic", Table1[[#This Row],[education_Graduation]] = 1, "Graduation", Table1[[#This Row],[education_Master]] = 1, "Master", Table1[[#This Row],[education_PhD]] = 1, "PhD")} -> PhD | AR9: {=_xlfn.IFS(Table1[[#This Row],[EducationLevel]] = "Graduation", "Graduate", Table1[[#This Row],[EducationLevel]] = "2n Cycle", "Undergraduate", Table1[[#This Row],[EducationLevel]] = "Basic", "Undergraduate", Table1[[#This Row],[EducationLevel]] = "Master", "Postgraduate", Table1[[#This Row],[EducationLevel]] = "PhD", "Postgraduate")} -> Postgraduate | AS9: 146 | AT9: 123 | AU9: 0 | AV9: 1 | AW9: Medium-Low Spender | AX9: NumWebPurchases | AY9: =IF(AND(O9 >= P9, O9 >= Q9), "Web", IF(AND(P9 >= O9, P9 >= Q9), "Catalog", "Store")) -> Web | AZ9: 8 | BA9: Not Accepted | BB9: =SUM(O9:Q9) -> 8 | BC9: =SUM(G9:L9) -> 169 | BD9: =(1-_xlfn.PERCENTRANK.INC($E:$E,E9,1))*10 -> 7 | BE9: =_xlfn.PERCENTRANK.INC($BB:$BB,BB9,1)*10 -> 3 | BF9: =_xlfn.PERCENTRANK.INC($BC:$BC,BC9,1)*10 -> 3 | BG9: =SUM(BD9:BF9) -> 13 | BH9: =_xlfn.PERCENTRANK.INC($BG:$BG,BG9,1)*10 -> 3 | BI9: =VLOOKUP(BH9,'Additional Data'!$E$1:$F$12,2,FALSE) -> At Risk | BJ9: =IF(G9 <= 'Additional Data'!$Q$2, "Low", IF(G9 <= 'Additional Data'!$Q$3, "Medium", "High")) -> Medium | BK9: =IF(K9 <= 'Additional Data'!$V$2, "Low", IF(K9 <= 'Additional Data'!$V$3, "Medium", "High")) -> Low | BL9: =IF(L9 <= 'Additional Data'!$AA$2, "Low", IF(L9 <= 'Additional Data'!$AA$3, "Medium", "High")) -> Medium | BM9: 8
A10: 30351 | B10: =IF(A10 <= 'Additional Data'!$B$2,"Low", IF(A10 <='Additional Data'!$B$3, "Medium", "High")) -> Low | C10: 1 | D10: 0 | E10: 19 | F10: =IF(E10<=7,"Very Recent",IF(E10<=30,"Recent",IF(E10<=60,"Mid","Old"))) -> Recent | G10: 14 | H10: 0 | I10: 24 | J10: 3 | K10: 3 | L10: 2 | M10: =INDEX('Additional Data'!$H$2:$M$2, MATCH(MAX(G10:L10), G10:L10,0)) -> 0 | N10: 1 | O10: 3 | P10: 0 | Q10: 2 | R10: 9 | S10: 0 | T10: 0 | U10: 0 | V10: 0 | W10: 0 | X10: 0 | Y10: 3 | Z10: 11 | AA10: 1 | AB10: 46 | AC10: {=_xlfn.IFS(AB10 < 30, "< 30", AB10 < 40, "30-39", AB10 < 50, "40-49", AB10 >= 50, "50+")} -> 40-49 | AD10: 2547 | AE10: 0 | AF10: 0 | AG10: 0 | AH10: 1 | AI10: 0 | AJ10: {=_xlfn.IFS(Table1[[#This Row],[marital_Divorced]] = 1, "Divorced", Table1[[#This Row],[marital_Married]] = 1, "Married", Table1[[#This Row],[marital_Single]] = 1, "Single", Table1[[#This Row],[marital_Together]] = 1, "Together", Table1[[#This Row],[marital_Widow]] = 1, "Widow")} -> Together | AK10: =IF(OR(Table1[[#This Row],[MaritalStatus]] = "Married", Table1[[#This Row],[MaritalStatus]] = "Together"), "Partner", IF(OR(Table1[[#This Row],[MaritalStatus]] = "Single",Table1[[#This Row],[MaritalStatus]] = "Divorced", Table1[[#This Row],[MaritalStatus]] = "Widow"), "Alone", "Other")) -> Partner | AL10: 0 | AM10: 0 | AN10: 0 | AO10: 0 | AP10: 1 | AQ10: {=_xlfn.IFS(Table1[[#This Row],[education_2n Cycle]] = 1, "2n Cycle", Table1[[#This Row],[education_Basic]] = 1, "Basic", Table1[[#This Row],[education_Graduation]] = 1, "Graduation", Table1[[#This Row],[education_Master]] = 1, "Master", Table1[[#This Row],[education_PhD]] = 1, "PhD")} -> PhD | AR10: {=_xlfn.IFS(Table1[[#This Row],[EducationLevel]] = "Graduation", "Graduate", Table1[[#This Row],[EducationLevel]] = "2n Cycle", "Undergraduate", Table1[[#This Row],[EducationLevel]] = "Basic", "Undergraduate", Table1[[#This Row],[EducationLevel]] = "Master", "Postgraduate", Table1[[#This Row],[EducationLevel]] = "PhD", "Postgraduate")} -> Postgraduate | AS10: 44 | AT10: 42 | AU10: 0 | AV10: 1 | AW10: Low Spender | AX10: NumWebPurchases | AY10: =IF(AND(O10 >= P10, O10 >= Q10), "Web", IF(AND(P10 >= O10, P10 >= Q10), "Catalog", "Store")) -> Web | AZ10: 5 | BA10: Not Accepted | BB10: =SUM(O10:Q10) -> 5 | BC10: =SUM(G10:L10) -> 46 | BD10: =(1-_xlfn.PERCENTRANK.INC($E:$E,E10,1))*10 -> 9 | BE10: =_xlfn.PERCENTRANK.INC($BB:$BB,BB10,1)*10 -> 1 | BF10: =_xlfn.PERCENTRANK.INC($BC:$BC,BC10,1)*10 -> 1 | BG10: =SUM(BD10:BF10) -> 11 | BH10: =_xlfn.PERCENTRANK.INC($BG:$BG,BG10,1)*10 -> 3 | BI10: =VLOOKUP(BH10,'Additional Data'!$E$1:$F$12,2,FALSE) -> At Risk | BJ10: =IF(G10 <= 'Additional Data'!$Q$2, "Low", IF(G10 <= 'Additional Data'!$Q$3, "Medium", "High")) -> Low | BK10: =IF(K10 <= 'Additional Data'!$V$2, "Low", IF(K10 <= 'Additional Data'!$V$3, "Medium", "High")) -> Medium | BL10: =IF(L10 <= 'Additional Data'!$AA$2, "Low", IF(L10 <= 'Additional Data'!$AA$3, "Medium", "High")) -> Low | BM10: 9
A11: 5648 | B11: =IF(A11 <= 'Additional Data'!$B$2,"Low", IF(A11 <='Additional Data'!$B$3, "Medium", "High")) -> Low | C11: 1 | D11: 1 | E11: 68 | F11: =IF(E11<=7,"Very Recent",IF(E11<=30,"Recent",IF(E11<=60,"Mid","Old"))) -> Old | G11: 28 | H11: 0 | I11: 6 | J11: 1 | K11: 1 | L11: 13 | M11: =INDEX('Additional Data'!$H$2:$M$2, MATCH(MAX(G11:L11), G11:L11,0)) -> 0 | N11: 1 | O11: 1 | P11: 0 | Q11: 0 | R11: 20 | S11: 1 | T11: 0 | U11: 0 | V11: 0 | W11: 0 | X11: 0 | Y11: 3 | Z11: 11 | AA11: 0 | AB11: 70 | AC11: {=_xlfn.IFS(AB11 < 30, "< 30", AB11 < 40, "30-39", AB11 < 50, "40-49", AB11 >= 50, "50+")} -> 50+ | AD11: 2267 | AE11: 0 | AF11: 0 | AG11: 0 | AH11: 1 | AI11: 0 | AJ11: {=_xlfn.IFS(Table1[[#This Row],[marital_Divorced]] = 1, "Divorced", Table1[[#This Row],[marital_Married]] = 1, "Married", Table1[[#This Row],[marital_Single]] = 1, "Single", Table1[[#This Row],[marital_Together]] = 1, "Together", Table1[[#This Row],[marital_Widow]] = 1, "Widow")} -> Together | AK11: =IF(OR(Table1[[#This Row],[MaritalStatus]] = "Married", Table1[[#This Row],[MaritalStatus]] = "Together"), "Partner", IF(OR(Table1[[#This Row],[MaritalStatus]] = "Single",Table1[[#This Row],[MaritalStatus]] = "Divorced", Table1[[#This Row],[MaritalStatus]] = "Widow"), "Alone", "Other")) -> Partner | AL11: 0 | AM11: 0 | AN11: 0 | AO11: 0 | AP11: 1 | AQ11: {=_xlfn.IFS(Table1[[#This Row],[education_2n Cycle]] = 1, "2n Cycle", Table1[[#This Row],[education_Basic]] = 1, "Basic", Table1[[#This Row],[education_Graduation]] = 1, "Graduation", Table1[[#This Row],[education_Master]] = 1, "Master", Table1[[#This Row],[education_PhD]] = 1, "PhD")} -> PhD | AR11: {=_xlfn.IFS(Table1[[#This Row],[EducationLevel]] = "Graduation", "Graduate", Table1[[#This Row],[EducationLevel]] = "2n Cycle", "Undergraduate", Table1[[#This Row],[EducationLevel]] = "Basic", "Undergraduate", Table1[[#This Row],[EducationLevel]] = "Master", "Postgraduate", Table1[[#This Row],[EducationLevel]] = "PhD", "Postgraduate")} -> Postgraduate | AS11: 36 | AT11: 23 | AU11: 1 | AV11: 2 | AW11: Low Spender | AX11: NumWebPurchases | AY11: =IF(AND(O11 >= P11, O11 >= Q11), "Web", IF(AND(P11 >= O11, P11 >= Q11), "Catalog", "Store")) -> Web | AZ11: 1 | BA11: Accepted | BB11: =SUM(O11:Q11) -> 1 | BC11: =SUM(G11:L11) -> 49 | BD11: =(1-_xlfn.PERCENTRANK.INC($E:$E,E11,1))*10 -> 4 | BE11: =_xlfn.PERCENTRANK.INC($BB:$BB,BB11,1)*10 -> 0 | BF11: =_xlfn.PERCENTRANK.INC($BC:$BC,BC11,1)*10 -> 1 | BG11: =SUM(BD11:BF11) -> 5 | BH11: =_xlfn.PERCENTRANK.INC($BG:$BG,BG11,1)*10 -> 0 | BI11: =VLOOKUP(BH11,'Additional Data'!$E$1:$F$12,2,FALSE) -> Churned Customer | BJ11: =IF(G11 <= 'Additional Data'!$Q$2, "Low", IF(G11 <= 'Additional Data'!$Q$3, "Medium", "High")) -> Medium | BK11: =IF(K11 <= 'Additional Data'!$V$2, "Low", IF(K11 <= 'Additional Data'!$V$3, "Medium", "High")) -> Low | BL11: =IF(L11 <= 'Additional Data'!$AA$2, "Low", IF(L11 <= 'Additional Data'!$AA$3, "Medium", "High")) -> Medium | BM11: 10
A12: 7500 | B12: =IF(A12 <= 'Additional Data'!$B$2,"Low", IF(A12 <='Additional Data'!$B$3, "Medium", "High")) -> Low | C12: 0 | D12: 0 | E12: 59 | F12: =IF(E12<=7,"Very Recent",IF(E12<=30,"Recent",IF(E12<=60,"Mid","Old"))) -> Mid | G12: 6 | H12: 16 | I12: 11 | J12: 11 | K12: 1 | L12: 16 | M12: =INDEX('Additional Data'!$H$2:$M$2, MATCH(MAX(G12:L12), G12:L12,0)) -> 0 | N12: 1 | O12: 2 | P12: 0 | Q12: 3 | R12: 8 | S12: 0 | T12: 0 | U12: 0 | V12: 0 | W12: 0 | X12: 0 | Y12: 3 | Z12: 11 | AA12: 0 | AB12: 44 | AC12: {=_xlfn.IFS(AB12 < 30, "< 30", AB12 < 40, "30-39", AB12 < 50, "40-49", AB12 >= 50, "50+")} -> 40-49 | AD12: 2752 | AE12: 0 | AF12: 1 | AG12: 0 | AH12: 0 | AI12: 0 | AJ12: {=_xlfn.IFS(Table1[[#This Row],[marital_Divorced]] = 1, "Divorced", Table1[[#This Row],[marital_Married]] = 1, "Married", Table1[[#This Row],[marital_Single]] = 1, "Single", Table1[[#This Row],[marital_Together]] = 1, "Together", Table1[[#This Row],[marital_Widow]] = 1, "Widow")} -> Married | AK12: =IF(OR(Table1[[#This Row],[MaritalStatus]] = "Married", Table1[[#This Row],[MaritalStatus]] = "Together"), "Partner", IF(OR(Table1[[#This Row],[MaritalStatus]] = "Single",Table1[[#This Row],[MaritalStatus]] = "Divorced", Table1[[#This Row],[MaritalStatus]] = "Widow"), "Alone", "Other")) -> Partner | AL12: 0 | AM12: 1 | AN12: 0 | AO12: 0 | AP12: 0 | AQ12: {=_xlfn.IFS(Table1[[#This Row],[education_2n Cycle]] = 1, "2n Cycle", Table1[[#This Row],[education_Basic]] = 1, "Basic", Table1[[#This Row],[education_Graduation]] = 1, "Graduation", Table1[[#This Row],[education_Master]] = 1, "Master", Table1[[#This Row],[education_PhD]] = 1, "PhD")} -> Basic | AR12: {=_xlfn.IFS(Table1[[#This Row],[EducationLevel]] = "Graduation", "Graduate", Table1[[#This Row],[EducationLevel]] = "2n Cycle", "Undergraduate", Table1[[#This Row],[EducationLevel]] = "Basic", "Undergraduate", Table1[[#This Row],[EducationLevel]] = "Master", "Postgraduate", Table1[[#This Row],[EducationLevel]] = "PhD", "Postgraduate")} -> Undergraduate | AS12: 45 | AT12: 29 | AU12: 0 | AV12: 0 | AW12: Low Spender | AX12: NumStorePurchases | AY12: =IF(AND(O12 >= P12, O12 >= Q12), "Web", IF(AND(P12 >= O12, P12 >= Q12), "Catalog", "Store")) -> Store | AZ12: 5 | BA12: Not Accepted | BB12: =SUM(O12:Q12) -> 5 | BC12: =SUM(G12:L12) -> 61 | BD12: =(1-_xlfn.PERCENTRANK.INC($E:$E,E12,1))*10 -> 4 | BE12: =_xlfn.PERCENTRANK.INC($BB:$BB,BB12,1)*10 -> 1 | BF12: =_xlfn.PERCENTRANK.INC($BC:$BC,BC12,1)*10 -> 2 | BG12: =SUM(BD12:BF12) -> 7 | BH12: =_xlfn.PERCENTRANK.INC($BG:$BG,BG12,1)*10 -> 1 | BI12: =VLOOKUP(BH12,'Additional Data'!$E$1:$F$12,2,FALSE) -> Churned Customer | BJ12: =IF(G12 <= 'Additional Data'!$Q$2, "Low", IF(G12 <= 'Additional Data'!$Q$3, "Medium", "High")) -> Low | BK12: =IF(K12 <= 'Additional Data'!$V$2, "Low", IF(K12 <= 'Additional Data'!$V$3, "Medium", "High")) -> Low | BL12: =IF(L12 <= 'Additional Data'!$AA$2, "Low", IF(L12 <= 'Additional Data'!$AA$3, "Medium", "High")) -> Medium | BM12: 11
A13: 63033 | B13: =IF(A13 <= 'Additional Data'!$B$2,"Low", IF(A13 <='Additional Data'!$B$3, "Medium", "High")) -> Medium | C13: 0 | D13: 0 | E13: 82 | F13: =IF(E13<=7,"Very Recent",IF(E13<=30,"Recent",IF(E13<=60,"Mid","Old"))) -> Old | G13: 194 | H13: 61 | I13: 480 | J13: 225 | K13: 112 | L13: 30 | M13: =INDEX('Additional Data'!$H$2:$M$2, MATCH(MAX(G13:L13), G13:L13,0)) -> 0 | N13: 1 | O13: 3 | P13: 4 | Q13: 8 | R13: 2 | S13: 0 | T13: 0 | U13: 0 | V13: 0 | W13: 0 | X13: 0 | Y13: 3 | Z13: 11 | AA13: 0 | AB13: 61 | AC13: {=_xlfn.IFS(AB13 < 30, "< 30", AB13 < 40, "30-39", AB13 < 50, "40-49", AB13 >= 50, "50+")} -> 50+ | AD13: 2385 | AE13: 1 | AF13: 0 | AG13: 0 | AH13: 0 | AI13: 0 | AJ13: {=_xlfn.IFS(Table1[[#This Row],[marital_Divorced]] = 1, "Divorced", Table1[[#This Row],[marital_Married]] = 1, "Married", Table1[[#This Row],[marital_Single]] = 1, "Single", Table1[[#This Row],[marital_Together]] = 1, "Together", Table1[[#This Row],[marital_Widow]] = 1, "Widow")} -> Divorced | AK13: =IF(OR(Table1[[#This Row],[MaritalStatus]] = "Married", Table1[[#This Row],[MaritalStatus]] = "Together"), "Partner", IF(OR(Table1[[#This Row],[MaritalStatus]] = "Single",Table1[[#This Row],[MaritalStatus]] = "Divorced", Table1[[#This Row],[MaritalStatus]] = "Widow"), "Alone", "Other")) -> Alone | AL13: 0 | AM13: 0 | AN13: 1 | AO13: 0 | AP13: 0 | AQ13: {=_xlfn.IFS(Table1[[#This Row],[education_2n Cycle]] = 1, "2n Cycle", Table1[[#This Row],[education_Basic]] = 1, "Basic", Table1[[#This Row],[education_Graduation]] = 1, "Graduation", Table1[[#This Row],[education_Master]] = 1, "Master", Table1[[#This Row],[education_PhD]] = 1, "PhD")} -> Graduation | AR13: {=_xlfn.IFS(Table1[[#This Row],[EducationLevel]] = "Graduation", "Graduate", Table1[[#This Row],[EducationLevel]] = "2n Cycle", "Undergraduate", Table1[[#This Row],[EducationLevel]] = "Basic", "Undergraduate", Table1[[#This Row],[EducationLevel]] = "Master", "Postgraduate", Table1[[#This Row],[EducationLevel]] = "PhD", "Postgraduate")} -> Graduate | AS13: 1072 | AT13: 1042 | AU13: 0 | AV13: 0 | AW13: High Spender | AX13: NumStorePurchases | AY13: =IF(AND(O13 >= P13, O13 >= Q13), "Web", IF(AND(P13 >= O13, P13 >= Q13), "Catalog", "Store")) -> Store | AZ13: 15 | BA13: Not Accepted | BB13: =SUM(O13:Q13) -> 15 | BC13: =SUM(G13:L13) -> 1102 | BD13: =(1-_xlfn.PERCENTRANK.INC($E:$E,E13,1))*10 -> 2 | BE13: =_xlfn.PERCENTRANK.INC($BB:$BB,BB13,1)*10 -> 5 | BF13: =_xlfn.PERCENTRANK.INC($BC:$BC,BC13,1)*10 -> 7 | BG13: =SUM(BD13:BF13) -> 14 | BH13: =_xlfn.PERCENTRANK.INC($BG:$BG,BG13,1)*10 -> 4 | BI13: =VLOOKUP(BH13,'Additional Data'!$E$1:$F$12,2,FALSE) -> At Risk | BJ13: =IF(G13 <= 'Additional Data'!$Q$2, "Low", IF(G13 <= 'Additional Data'!$Q$3, "Medium", "High")) -> Medium | BK13: =IF(K13 <= 'Additional Data'!$V$2, "Low", IF(K13 <= 'Additional Data'!$V$3, "Medium", "High")) -> High | BL13: =IF(L13 <= 'Additional Data'!$AA$2, "Low", IF(L13 <= 'Additional Data'!$AA$3, "Medium", "High")) -> Medium | BM13: 12
... A2206: 52869 | B2206: =IF(A2206 <= 'Additional Data'!$B$2,"Low", IF(A2206 <='Additional Data'!$B$3, "Medium", "High")) -> Medium | C2206: 1 | D2206: 1 | E2206: 40 | F2206: =IF(E2206<=7,"Very Recent",IF(E2206<=30,"Recent",IF(E2206<=60,"Mid","Old"))) -> Mid | G2206: 84 | H2206: 3 | I2206: 61 | J2206: 2 | K2206: 1 | L2206: 21 | M2206: =INDEX('Additional Data'!$H$2:$M$2, MATCH(MAX(G2206:L2206), G2206:L2206,0)) -> 0 | N2206: 3 | O2206: 3 | P2206: 1 | Q2206: 4 | R2206: 7 | S2206: 0 | T2206: 0 | U2206: 0 | V2206: 0 | W2206: 0 | X2206: 0 | Y2206: 3 | Z2206: 11 | AA2206: 1 | AB2206: 66 | AC2206: {=_xlfn.IFS(AB2206 < 30, "< 30", AB2206 < 40, "30-39", AB2206 < 50, "40-49", AB2206 >= 50, "50+")} -> 50+ | AD2206: 2781 | AE2206: 0 | AF2206: 1 | AG2206: 0 | AH2206: 0 | AI2206: 0 | AJ2206: {=_xlfn.IFS(Table1[[#This Row],[marital_Divorced]] = 1, "Divorced", Table1[[#This Row],[marital_Married]] = 1, "Married", Table1[[#This Row],[marital_Single]] = 1, "Single", Table1[[#This Row],[marital_Together]] = 1, "Together", Table1[[#This Row],[marital_Widow]] = 1, "Widow")} -> Married | AK2206: =IF(OR(Table1[[#This Row],[MaritalStatus]] = "Married", Table1[[#This Row],[MaritalStatus]] = "Together"), "Partner", IF(OR(Table1[[#This Row],[MaritalStatus]] = "Single",Table1[[#This Row],[MaritalStatus]] = "Divorced", Table1[[#This Row],[MaritalStatus]] = "Widow"), "Alone", "Other")) -> Partner | AL2206: 0 | AM2206: 0 | AN2206: 0 | AO2206: 0 | AP2206: 1 | AQ2206: {=_xlfn.IFS(Table1[[#This Row],[education_2n Cycle]] = 1, "2n Cycle", Table1[[#This Row],[education_Basic]] = 1, "Basic", Table1[[#This Row],[education_Graduation]] = 1, "Graduation", Table1[[#This Row],[education_Master]] = 1, "Master", Table1[[#This Row],[education_PhD]] = 1, "PhD")} -> PhD | AR2206: {=_xlfn.IFS(Table1[[#This Row],[EducationLevel]] = "Graduation", "Graduate", Table1[[#This Row],[EducationLevel]] = "2n Cycle", "Undergraduate", Table1[[#This Row],[EducationLevel]] = "Basic", "Undergraduate", Table1[[#This Row],[EducationLevel]] = "Master", "Postgraduate", Table1[[#This Row],[EducationLevel]] = "PhD", "Postgraduate")} -> Postgraduate | AS2206: 151 | AT2206: 130 | AU2206: 0 | AV2206: 2 | AW2206: Medium-Low Spender | AX2206: NumStorePurchases | AY2206: =IF(AND(O2206 >= P2206, O2206 >= Q2206), "Web", IF(AND(P2206 >= O2206, P2206 >= Q2206), "Catalog", "Store")) -> Store | AZ2206: 8 | BA2206: Not Accepted | BB2206: =SUM(O2206:Q2206) -> 8 | BC2206: =SUM(G2206:L2206) -> 172 | BD2206: =(1-_xlfn.PERCENTRANK.INC($E:$E,E2206,1))*10 -> 6 | BE2206: =_xlfn.PERCENTRANK.INC($BB:$BB,BB2206,1)*10 -> 3 | BF2206: =_xlfn.PERCENTRANK.INC($BC:$BC,BC2206,1)*10 -> 3 | BG2206: =SUM(BD2206:BF2206) -> 12 | BH2206: =_xlfn.PERCENTRANK.INC($BG:$BG,BG2206,1)*10 -> 3 | BI2206: =VLOOKUP(BH2206,'Additional Data'!$E$1:$F$12,2,FALSE) -> At Risk | BJ2206: =IF(G2206 <= 'Additional Data'!$Q$2, "Low", IF(G2206 <= 'Additional Data'!$Q$3, "Medium", "High")) -> Medium | BK2206: =IF(K2206 <= 'Additional Data'!$V$2, "Low", IF(K2206 <= 'Additional Data'!$V$3, "Medium", "High")) -> Low | BL2206: =IF(L2206 <= 'Additional Data'!$AA$2, "Low", IF(L2206 <= 'Additional Data'!$AA$3, "Medium", "High")) -> Medium | BM2206: 2205

Sheet Additional Data
A1: Quartile | B1: Values | C1: Notes | E1: RFM_Score | F1: Customer_Segment | O1: Wine | P1: Quantile | Q1: Values | R1: Notes | T1: Sweet | U1: Quantile | V1: Values | W1: Notes | Y1: Gold | Z1: Quartile | AA1: Values | AB1: Note
A2: Q1 | B2: =_xlfn.QUARTILE.INC('Campaign Data'!A:A,1) -> 35196 | C2: Lower Income | E2: 10 | F2: Top Customer | P2: Q1 | Q2: =_xlfn.QUARTILE.INC('Campaign Data'!G:G,1) -> 24 | R2: Low Spend | U2: Q1 | V2: =_xlfn.QUARTILE.INC('Campaign Data'!K2:K2206, 1) -> 1 | W2: Low Spend | Z2: Q1 | AA2: =_xlfn.QUARTILE.INC(Table1[MntGoldProds],1) -> 9 | AB2: Low Spend
A3: Q3 | B3: =_xlfn.QUARTILE.INC('Campaign Data'!A:A,3) -> 68281 | C3: High Income | E3: 9 | F3: Top Customer | P3: Q3 | Q3: =_xlfn.QUARTILE.INC('Campaign Data'!G:G,3) -> 507 | R3: High Spend | U3: Q3 | V3: =_xlfn.QUARTILE.INC(Table1[MntSweetProducts],3) -> 34 | W3: High Spend | Z3: Q3 | AA3: =_xlfn.QUARTILE.INC(Table1[MntGoldProds],3) -> 56 | AB3: High Spend
E4: 8 | F4: Top Customer
E5: 7 | F5: Loyal Customer
E6: 6 | F6: Loyal Customer
E7: 5 | F7: Loyal Customer
E8: 4 | F8: At Risk
E9: 3 | F9: At Risk
E10: 2 | F10: Churned Customer
E11: 1 | F11: Churned Customer
E12: 0 | F12: Churned Customer

Sheet Conversion Analysis
A1: Campaign Name | B1: Conversion Rate per Campaign | D1: Campaign Name | E1: Avg. Customers Spending
A2: Campaign 5 | B2: 0.073015873 | D2: Campaign 5 | E2: 1615
A3: Campaign 4 | B3: 0.074376417 | D3: Campaign 4 | E3: 1138
A4: Campaign 3 | B4: 0.073922902 | D4: Campaign 3 | E4: 721
A5: Campaign 2 | B5: 0.013605442 | D5: Campaign 2 | E5: 1308
A6: Campaign 1 | B6: 0.064399093 | D6: Campaign 1 | E6: 1484

Sheet Customer Spending Segment
A8: AcceptedCmp1 | B8: 1 | E8: AcceptedCmp2 | F8: 1 | I8: Campaign 1 - 5
I9: Spending Level | J9: # Accepted Cmp | K9: Avg Spending (USD)
A10: Row Labels | B10: Count of ID | C10: Average of Monetary | E10: Row Labels | F10: Count of ID | G10: Average of Monetary | I10: High Spender | J10: =111+23+51+87+146 -> 418 | K10: =1684+1552+1620+1611+1697 -> 8164
A11: High Spender | B11: 111 | C11: 1684.4955 | E11: High Spender | F11: 23 | G11: 1551.9565 | I11: Medium-High Spender | J11: =29+4+36+57+15 -> 141 | K11: =799+757+729+729+812 -> 3826
A12: Medium-High Spender | B12: 29 | C12: 798.65517 | E12: Low Spender | F12: 2 | G12: 46 | I12: Medium-Low Spender | J12: =2+1+29+19 -> 51 | K12: =319+416+217+252 -> 1204
A13: Medium-Low Spender | B13: 2 | C13: 318.5 | E13: Medium-High Spender | F13: 4 | G13: 756.75 | I13: Low Spender | J13: =2+47+1 -> 50 | K13: =46+49+54 -> 149
E14: Medium-Low Spender | F14: 1 | G14: 416
A17: AcceptedCmp3 | B17: 1 | E17: AcceptedCmp4 | F17: 1
A19: Row Labels | B19: Count of ID | C19: Average of Monetary | E19: Row Labels | F19: Count of ID | G19: Average of Monetary
A20: High Spender | B20: 51 | C20: 1620.1373 | E20: High Spender | F20: 87 | G20: 1610.7701
A21: Low Spender | B21: 47 | C21: 48.829787 | E21: Low Spender | F21: 1 | G21: 54
A22: Medium-High Spender | B22: 36 | C22: 728.88889 | E22: Medium-High Spender | F22: 57 | G22: 729.49123
A23: Medium-Low Spender | B23: 29 | C23: 216.75862 | E23: Medium-Low Spender | F23: 19 | G23: 252
A24: Grand Total | B24: 163 | C24: 720.53988 | E24: Grand Total | F24: 164 | G24: 1137.561
A28: AcceptedCmp5 | B28: 1
A30: Row Labels | B30: Count of ID | C30: Average of Monetary
A31: High Spender | B31: 146 | C31: 1697.4521
A32: Medium-High Spender | B32: 15 | C32: 812.06667
A33: Grand Total | B33: 161 | C33: 1614.9627

Sheet Cmp Cost Analysis
A1: Cmp1 | F1: Cmp4
A2: Cmp1 Cust. Response | B2: Count of ID | C2: Average Revenue | D2: Total Revenue | F2: Cmp4 Cust. Response | G2: Count of ID | H2: Average Revenue | I2: Total Revenue | K2: Campaign Name | L2: Avg Revenue (USD) | M2: Converted Customers | N2: Total Revenue (USD) | O2: Campaign Cost (USD) | P2: Revenue Cost Ratio (USD) | Q2: Cost Per Conversion (USD) | R2: Cost Revenue Ratio (%)
A3: 0 | B3: 2063 | C3: 546.42026 | D3: 1127265 | F3: 0 | G3: 2041 | H3: 564.1754 | I3: 1151482 | K3: Campaign 1 | L3: 1484 | M3: 142 | N3: 210777 | O3: 3 | P3: =N3/O3 -> 70259 | Q3: =O3/M3 -> 0.021126761 | R3: =O3/N3*100 -> 0.0014233052
A4: 1 | B4: 142 | C4: 1484.3451 | D4: 210777 | F4: 1 | G4: 164 | H4: 1137.561 | I4: 186560 | K4: Campaign 2 | L4: 1308 | M4: 30 | N4: 39239 | O4: 3 | P4: =N4/O4 -> 13079.667 | Q4: =O4/M4 -> 0.1 | R4: =O4/N4*100 -> 0.0076454548
K5: Campaign 3 | L5: 721 | M5: 163 | N5: 117448 | O5: 3 | P5: =N5/O5 -> 39149.333 | Q5: =O5/M5 -> 0.018404908 | R5: =O5/N5*100 -> 0.0025543219
K6: Campaign 4 | L6: 1138 | M6: 164 | N6: 186560 | O6: 3 | P6: =N6/O6 -> 62186.667 | Q6: =O6/M6 -> 0.018292683 | R6: =O6/N6*100 -> 0.0016080617
A7: Cmp2 | F7: Cmp5 | K7: Campaign 5 | L7: 1615 | M7: 161 | N7: 260009 | O7: 3 | P7: =N7/O7 -> 86669.667 | Q7: =O7/M7 -> 0.01863354 | R7: =O7/N7*100 -> 0.0011538062
A8: Cmp2 Cust. Response | B8: Count of ID | C8: Average Revenue | D8: Total Revenue | F8: Cmp5 Cust. Response | G8: Count of ID | H8: Average Revenue | I8: Total Revenue
A9: 0 | B9: 2175 | C9: 597.15494 | D9: 1298812 | F9: 0 | G9: 2044 | H9: 527.41341 | I9: 1078033
A10: 1 | B10: 30 | C10: 1307.6667 | D10: 39230 | F10: 1 | G10: 161 | H10: 1614.9627 | I10: 260009
K11: Campaign Name | L11: Revenue Cost Ratio (USD) | N11: Campaign Name | O11: Cost Per Conversion (USD) | Q11: Campaign Name | R11: Cost Revenue Ratio (%)
K12: Campaign 1 | L12: 70259 | N12: Campaign 1 | O12: 0.021126761 | Q12: Campaign 1 | R12: 0.0014233052
A13: Cmp3 | K13: Campaign 2 | L13: 13079.667 | N13: Campaign 2 | O13: 0.1 | Q13: Campaign 2 | R13: 0.0076454548
A14: Cmp3 Cust. Response | B14: Count of ID | C14: Average Revenue | D14: Total Revenue | K14: Campaign 3 | L14: 39149.333 | N14: Campaign 3 | O14: 0.018404908 | Q14: Campaign 3 | R14: 0.0025543219
A15: 0 | B15: 2042 | C15: 597.74437 | D15: 1220594 | K15: Campaign 4 | L15: 62186.667 | N15: Campaign 4 | O15: 0.018292683 | Q15: Campaign 4 | R15: 0.0016080617
A16: 1 | B16: 163 | C16: 720.53988 | D16: 117448 | K16: Campaign 5 | L16: 86669.667 | N16: Campaign 5 | O16: 0.01863354 | Q16: Campaign 5 | R16: 0.0011538062

Sheet Customer Age Segment
A3: Row Labels | B3: Campaign 1 | C3: Row Labels | D3: Campaign 2 | E3: Row Labels | F3: Campaign 3 | G3: Row Labels | H3: Campaign 4 | I3: Row Labels | J3: Campaign 5
A4: 50+ | B4: 0.54225352 | C4: 50+ | D4: 0.63333333 | E4: 50+ | F4: 0.41104294 | G4: 50+ | H4: 0.6402439 | I4: < 30 | J4: 0.055900621
A5: 40-49 | B5: 0.23239437 | C5: 40-49 | D5: 0.2 | E5: 40-49 | F5: 0.32515337 | G5: 40-49 | H5: 0.22560976 | I5: 30-39 | J5: 0.22981366
A6: 30-39 | B6: 0.19014085 | C6: 30-39 | D6: 0.13333333 | E6: 30-39 | F6: 0.2392638 | G6: 30-39 | H6: 0.1097561 | I6: 40-49 | J6: 0.22360248
A7: < 30 | B7: 0.035211268 | C7: < 30 | D7: 0.033333333 | E7: < 30 | F7: 0.024539877 | G7: < 30 | H7: 0.024390244 | I7: 50+ | J7: 0.49068323
A12: AcceptedCmp1 | B12: 1 | D12: AcceptedCmp2 | E12: 1
A14: Row Labels | B14: Average of Monetary | D14: Row Labels | E14: Average of Monetary | G14: Age Group | H14: Avg Spending
A15: < 30 | B15: 1547.4 | D15: < 30 | E15: 1378 | G15: 40-49 | H15: =1487+1368+605+1129+1585 -> 6174
A16: 30-39 | B16: 1518.5926 | D16: 30-39 | E16: 1541.25 | G16: 50 + | H16: 6210
A17: 40-49 | B17: 1487.3636 | D17: 40-49 | E17: 1368.1667 | G17: < 30 | H17: 6795
A18: 50+ | B18: 1466.9481 | D18: 50+ | E18: 1235.6842 | G18: 30-39 | H18: =1519+1541+748+1418+1603 -> 6829
A23: AcceptedCmp3 | B23: 1 | D23: AcceptedCmp4 | E23: 1
A25: Row Labels | B25: Average of Monetary | D25: Row Labels | E25: Average of Monetary
A26: < 30 | B26: 773.25 | D26: < 30 | E26: 1479.75
A27: 30-39 | B27: 748.33333 | D27: 30-39 | E27: 1417.6111
A28: 40-49 | B28: 604.84906 | D28: 40-49 | E28: 1128.9189
A29: 50+ | B29: 792.73134 | D29: 50+ | E29: 1079.5619
A34: AcceptedCmp5 | B34: 1
A36: Row Labels | B36: Average of Monetary
A37: < 30 | B37: 1617.3333
A38: 30-39 | B38: 1603.0541
A39: 40-49 | B39: 1584.6944
A40: 50+ | B40: 1634.0633

Sheet Channel Analysis
A4: Row Labels | B4: Cmp1_Accepted | C4: Row Labels | D4: Cmp2_Accepted | E4: Row Labels | F4: Cmp3_Accepted | G4: Row Labels | H4: Cmp4_Accepted | I4: Row Labels | J4: Cmp5_Accepted
A5: Catalog | B5: 0.25352113 | C5: Catalog | D5: 0.13333333 | E5: Catalog | F5: 0.14110429 | G5: Catalog | H5: 0.079268293 | I5: Catalog | J5: 0.19875776
A6: Store | B6: 0.53521127 | C6: Store | D6: 0.76666667 | E6: Store | F6: 0.45398773 | G6: Store | H6: 0.6097561 | I6: Store | J6: 0.65838509
A7: Web | B7: 0.21126761 | C7: Web | D7: 0.1 | E7: Web | F7: 0.40490798 | G7: Web | H7: 0.31097561 | I7: Web | J7: 0.14285714
A12: Cmp_Name | B12: Conversion Rate | D12: Cmp_Name | E12: Conversion Rate | G12: Cmp_Name | H12: Conversion Rate
A13: Campaign 1 | B13: 54 | D13: Campaign 1 | E13: 25 | G13: Campaign 1 | H13: 21
A14: Campaign 2 | B14: 77 | D14: Campaign 2 | E14: 13 | G14: Campaign 2 | H14: 10
A15: Campaign 3 | B15: 45 | D15: Campaign 3 | E15: 14 | G15: Campaign 3 | H15: 40
A16: Campaign 4 | B16: 61 | D16: Campaign 4 | E16: 8 | G16: Campaign 4 | H16: 31
A17: Campaign 5 | B17: 66 | D17: Campaign 5 | E17: 20 | G17: Campaign 5 | H17: 14
A23: AcceptedCmp1 | B23: 1 | C23: AcceptedCmp2 | D23: 1 | E23: AcceptedCmp3 | F23: 1 | G23: AcceptedCmp4 | H23: 1 | I23: AcceptedCmp5 | J23: 1
A25: Row Labels | B25: Average of Monetary | C25: Row Labels | D25: Average Spend per Channel | E25: Row Labels | F25: Average of Monetary | G25: Row Labels | H25: Average of Monetary | I25: Row Labels | J25: Average of Monetary
B26: 1596.8889 | C26: Catalog | D26: 1829.25 | E26: Catalog | F26: 1148.087 | G26: Catalog | H26: 1760.4615 | I26: Catalog | J26: 1741.6875
A27: Store | B27: 1557.1184 | C27: Store | D27: 1304.2609 | E27: Store | F27: 670.31081 | G27: Store | H27: 1188.51 | I27: Store | J27: 1600.1321
A28: Web | B28: 1164.9333 | C28: Web | D28: 638.33333 | E28: Web | F28: 627.86364 | G28: Web | H28: 878.88235 | I28: Web | J28: 1507
A31: Channel Name | B31: Average Revenue
A32: Catalog | B32: =1597+1829+1148+1760+1742 -> 8076
A33: Store | B33: =1557+1304+670+1189+1600 -> 6320
A34: Website | B34: =1165+638+628+879+1507 -> 4817
A40: AcceptedCmp1 | B40: 1 | E40: AcceptedCmp2 | F40: 1 | I40: AcceptedCmp3 | J40: 1
A42: Row Labels | B42: Count of ID | C42: Total Revenue | E42: Row Labels | F42: Count of ID | G42: Total Revenue | I42: Row Labels | J42: Count of ID | K42: Total Revenue
A43: Catalog | B43: 36 | C43: 57488 | E43: Catalog | F43: 4 | G43: 7317 | I43: Catalog | J43: 23 | K43: 26406
A44: Store | B44: 76 | C44: 118341 | E44: Store | F44: 23 | G44: 29998 | I44: Store | J44: 74 | K44: 49603
A45: Web | B45: 30 | C45: 34948 | E45: Web | F45: 3 | G45: 1915 | I45: Web | J45: 66 | K45: 41439
A47: AcceptedCmp4 | B47: 1 | E47: AcceptedCmp5 | F47: 1
A49: Row Labels | B49: Count of ID | C49: Total Revenue | E49: Row Labels | F49: Count of ID | G49: Total Revenue
A50: Catalog | B50: 13 | C50: 22886 | E50: Catalog | F50: 32 | G50: 55734
A51: Store | B51: 100 | C51: 118851 | E51: Store | F51: 106 | G51: 169614
A52: Web | B52: 51 | C52: 44823 | E52: Web | F52: 23 | G52: 34661
A54: Channel | B54: Avg Revenue (USD) | C54: Converted Customer | D54: Total Revenue | E54: Campaign Cost (USD) | F54: Revenue Cost Ratio (USD) | G54: Cost Per Conversion (USD) | H54: Cost Revenue Ratio (%)
A55: Store | B55: =1557+1304+670+1189+1600 -> 6320 | C55: =76+23+74+100+106 -> 379 | D55: =118341+29998+49603+118851+169614 -> 486407 | E55: 15 | F55: =Table22[[#This Row],[Total Revenue]]/Table22[[#This Row],[Campaign Cost (USD)]] -> 32427.133 | G55: =Table22[[#This Row],[Campaign Cost (USD)]]/Table22[[#This Row],[Converted Customer]] -> 0.039577836 | H55: =Table22[[#This Row],[Campaign Cost (USD)]]/Table22[[#This Row],[Total Revenue]]*100 -> 0.0030838372
A56: Catalog | B56: =1597+1829+1148+1760+1742 -> 8076 | C56: =36+4+23+13+32 -> 108 | D56: =57488+7317+26406+22886+55734 -> 169831 | E56: 15 | F56: =Table22[[#This Row],[Total Revenue]]/Table22[[#This Row],[Campaign Cost (USD)]] -> 11322.067 | G56: =Table22[[#This Row],[Campaign Cost (USD)]]/Table22[[#This Row],[Converted Customer]] -> 0.13888889 | H56: =Table22[[#This Row],[Campaign Cost (USD)]]/Table22[[#This Row],[Total Revenue]]*100 -> 0.0088323098
A57: Website | B57: =1165+638+628+879+1507 -> 4817 | C57: =30+3+66+51+23 -> 173 | D57: =34948+1915+41439+44823+34661 -> 157786 | E57: 15 | F57: =Table22[[#This Row],[Total Revenue]]/Table22[[#This Row],[Campaign Cost (USD)]] -> 10519.067 | G57: =Table22[[#This Row],[Campaign Cost (USD)]]/Table22[[#This Row],[Converted Customer]] -> 0.086705202 | H57: =Table22[[#This Row],[Campaign Cost (USD)]]/Table22[[#This Row],[Total Revenue]]*100 -> 0.0095065468
A60: Channel | B60: Revenue Cost Ratio (USD)
A61: Catalog | B61: 32427.133
A62: Store | B62: 11322.067
A63: Website | B63: 10519.067
A66: Channel | B66: Cost Per Conversion (USD)
A67: Catalog | B67: 0.13888889
A68: Store | B68: 0.039577836
...

Sheet Customer Recency Analysis
A1: AcceptedCmp1 | B1: 1 | C1: AcceptedCmp2 | D1: 1 | E1: AcceptedCmp3 | F1: 1 | G1: AcceptedCmp4 | H1: 1 | I1: AcceptedCmp5 | J1: 1
A3: Row Labels | B3: Average of Monetary | C3: Row Labels | D3: Average of Monetary | E3: Row Labels | F3: Average of Monetary | G3: Row Labels | H3: Average of Monetary | I3: Row Labels | J3: Average of Monetary
A4: Mid | B4: 1464.35 | C4: Mid | D4: 1349.25 | E4: Mid | F4: 742.51064 | G4: Mid | H4: 1067.9756 | I4: Mid | J4: 1584.5 | K4: =1464+1349+743+1068+1585 -> 6209
A5: Old | B5: 1557.9804 | C5: Old | D5: 1419 | E5: Old | F5: 887.24528 | G5: Old | H5: 1130.0704 | I5: Old | J5: 1637.871 | K5: =1558+1419+887+1130+1638 -> 6632
A6: Recent | B6: 1487.3429 | C6: Recent | D6: 1054.5714 | E6: Recent | F6: 526.87755 | G6: Recent | H6: 1223.4286 | I6: Recent | J6: 1651.4565 | K6: =1487+1055+527+1223+1651 -> 5943
A7: Very Recent | B7: 1293.0625 | C7: Very Recent | D7: 1291.5 | E7: Very Recent | F7: 693.5 | G7: Very Recent | H7: 1115.4 | I7: Very Recent | J7: 1449.5455 | K7: =1293+1292+694+1115+1450 -> 5844
A9: Row Labels | B9: Conversion Rate Cmp 1(%) | C9: Row Labels | D9: Conversion Rate Cmp 2(%) | E9: Row Labels | F9: Conversion Rate Cmp 3(%) | G9: Row Labels | H9: Conversion Rate Cmp 4(%) | I9: Row Labels | J9: Conversion Rate Cmp 5(%)
A10: Mid | B10: 0.28169014 | C10: Mid | D10: 0.13333333 | E10: Mid | F10: 0.28834356 | G10: Mid | H10: 0.25 | I10: Mid | J10: 0.26086957
A11: Old | B11: 0.35915493 | C11: Old | D11: 0.5 | E11: Old | F11: 0.32515337 | G11: Old | H11: 0.43292683 | I11: Old | J11: 0.38509317
A12: Recent | B12: 0.24647887 | C12: Recent | D12: 0.23333333 | E12: Recent | F12: 0.3006135 | G12: Recent | H12: 0.25609756 | I12: Recent | J12: 0.28571429
A13: Very Recent | B13: 0.11267606 | C13: Very Recent | D13: 0.13333333 | E13: Very Recent | F13: 0.085889571 | G13: Very Recent | H13: 0.06097561 | I13: Very Recent | J13: 0.068322981

Sheet Graphics

Sheet Key Insight
